Workbook

Sheet INPUT_매출
A1: 피트니스 센터 P&L 시뮬레이터 — 매출 INPUT
A2: ※ 파란 글씨 셀에 수동 입력 | 검정 셀은 자동 계산 | 노란 배경 = 입력 필요
A3: 항목 구분 | B3: 세부 항목 | C3: 변수 A | D3: 값 A | E3: 변수 B | F3: 값 B | G3: 결과/소계
A4: ■ MBS 매출 (회원권)
B5: ① 구독 매출
B6: 구독 신규 매출 | C6: 신규 구독자 (명) | D6: 30 | E6: 객단가 (원) | F6: 85000 | G6: =D6*F6
B7: 구독 연장 매출 | C7: 만료 대상자 (명) | D7: 180 | E7: 잔존율 (%) | F7: 82
C8: 연장 객단가 (원) | D8: 85000 | G8: =ROUND(D7*(F7/100),0)*D8
B9: ② 기간 매출
B10: 기간권 신규 매출 | C10: 신규 결제자 (명) | D10: 25 | E10: 객단가 (원) | F10: 180000 | G10: =D10*F10
B11: 기간권 재등록 매출 | C11: 재등록 대상자 (명) | D11: 60 | E11: 재등록율 (%) | F11: 65
C12: 재등록 객단가 (원) | D12: 160000 | G12: =ROUND(D11*(F11/100),0)*D12
B13: ③ 1일권
B14: 1일권 매출 | C14: 이용자 수 (명) | D14: 40 | E14: 객단가 (원) | F14: 12000 | G14: =D14*F14
B15: ④ 법인 / 옵션 (수동 입력)
B16: 법인 매출 | G16: 0
B17: 옵션 매출 | G17: 0
A18: MBS 매출 합계 | G18: =G6+G8+G10+G12+G14+G16+G17
A20: ■ PT 매출 (퍼스널 트레이닝)
B21: ① PT 재등록 매출
B22: PT 재등록 매출 | C22: 재등록 대상자 (명) | D22: 25 | E22: 재등록율 (%) | F22: 70
C23: 재등록 객단가 (원) | D23: 550000 | G23: =ROUND(D22*(F22/100),0)*D23
B24: ② PT 체험권 판매 매출
B25: 체험권 판매 매출 | C25: 체험권 판매 수 (명) | D25: 15 | E25: 객단가 (원) | F25: 99000 | G25: =D25*F25
B26: ③ PT 체험→정규 전환 매출 (체험권 판매 수 자동 연동)
B27: 체험→정규 전환 매출 | C27: 전환율 (%) | D27: 40 | E27: 전환 객단가 (원) | F27: 480000 | G27: =ROUND(D25*(D27/100),0)*F27
B28: ④ PT 신규 오가닉 매출
B29: 신규 오가닉 매출 | C29: 신규 결제자 (명) | D29: 8 | E29: 객단가 (원) | F29: 480000 | G29: =D29*F29
B30: ⑤ PT 대관 매출 (수동 입력)
B31: PT 대관 매출 | G31: 0
A32: PT 매출 합계 | G32: =G23+G25+G27+G29+G31
A34: ■ TB 매출 (프로그램 / 레슨)
B35: 실속 매출 | G35: 3000000
B36: 프리미엄 매출 | G36: 2000000
B37: 상시프로모 매출 | G37: 500000
A38: TB 매출 합계 | G38: =G35+G36+G37
A39: ★ PB 매출 합계 (핸들링 가능 = MBS + PT + TB + 옵션) | G39: =G18+G32+G38
A41: ■ 입점업체 매출 (수동 입력 / 업체명 수정 가능, 최대 8개)
B42: 입점업체 1 | G42: 0
B43: 입점업체 2 | G43: 0
...

Sheet INPUT_비용
A1: 피트니스 센터 P&L 시뮬레이터 — 비용 INPUT
A2: ※ 파란 글씨 셀에 수동 입력 | 검정 셀은 자동 계산 | 결제수수료는 매출 연동 자동 계산
A3: 항목 구분 | B3: 세부 항목 | C3: 변수 A | D3: 값 A | E3: 변수 B | F3: 값 B | G3: 결과/소계
A4: ■ COS — 매출원가 (Cost of Sales)
B5: ① PT 강사료 (수동 입력)
B6: PT 강사료 합계 | G6: 3500000
B7: ② 입점업체 수수료 (업체명 수정 가능 / 최대 8개)
B8: 입점업체 1 수수료 | G8: 0
B9: 입점업체 2 수수료 | G9: 0
B10: 입점업체 3 수수료 | G10: 0
A11: 입점업체 수수료 소계 | G11: =SUM(G8:G10)
B12: ③ 결제수수료 = 총 매출 × 2.16% (자동 계산, 수정 불필요)
B13: 결제수수료 | C13: =INPUT_매출 총 매출 × 2.16% 자동 연동 | G13: =INPUT_매출!G50*0.0216
A14: COS 합계 | G14: =G6+G11+G13
A16: ■ SG&A — 비인건성 판관비
B17: ① 임관비 (임차료 / 고정관리비 / 전기료 / 수도료)
B18: 임차료 | G18: 6000000
B19: 고정관리비 | G19: 300000
B20: 전기료 | G20: 400000
B21: 수도료 | G21: 100000
A22: 임관비 소계 | G22: =SUM(G18:G21)
B23: ② 기타 비인건성 비용
B24: 세탁비 | G24: 150000
B25: 소모품비 | G25: 300000
B26: 수선비 | G26: 100000
B27: 마케팅비 | G27: 800000
B28: 기타비용 | G28: 200000
A29: 비인건성 판관비 합계 | G29: =G22+SUM(G24:G28)
A31: ■ SG&A — 인건비성 판관비
B32: ① BG 인건비 (직영, 수동 입력)
B33: BG 인건비 합계 | G33: 12000000
B34: ② TB 인건비 (협력/파트, 수동 입력)
B35: TB 인건비 합계 | G35: 8000000
A36: 인건비성 판관비 합계 | G36: =G33+G35
A38: ◆ 총 비용 합계 | G38: =G14+G29+G36

Sheet P&L
A1: 월간 손익계산서 (P&L) — 모든 수치는 INPUT 시트 자동 연동
A3: ▶ SALES TOTAL
A4: MBS 매출
A5: 구독 신규 매출 | C5: =INPUT_매출!G6
A6: 구독 연장 매출 | C6: =INPUT_매출!G8
A7: 기간권 신규 매출 | C7: =INPUT_매출!G10
A8: 기간권 재등록 | C8: =INPUT_매출!G12
A9: 1일권 매출 | C9: =INPUT_매출!G14
A10: 법인 매출 | C10: =INPUT_매출!G16
A11: 옵션 매출 | C11: =INPUT_매출!G17
A12: MBS 소계 | C12: =INPUT_매출!G18
A13: PT 매출
A14: PT 재등록 매출 | C14: =INPUT_매출!G23
A15: PT 체험권 판매 | C15: =INPUT_매출!G25
A16: PT 체험→정규 전환 | C16: =INPUT_매출!G27
A17: PT 신규 오가닉 | C17: =INPUT_매출!G29
A18: PT 대관 매출 | C18: =INPUT_매출!G31
A19: PT 소계 | C19: =INPUT_매출!G32
A20: TB 매출
A21: 실속 | C21: =INPUT_매출!G35
A22: 프리미엄 | C22: =INPUT_매출!G36
A23: 상시프로모 | C23: =INPUT_매출!G37
A24: TB 소계 | C24: =INPUT_매출!G38
A25: ★ PB 매출 합계 (핸들링 가능 = MBS+PT+TB) | C25: =INPUT_매출!G39
A26: 입점업체 매출
A27: 입점업체 1 | C27: =INPUT_매출!G42
A28: 입점업체 2 | C28: =INPUT_매출!G43
A29: 입점업체 3 | C29: =INPUT_매출!G44
A30: 입점업체 소계 | C30: =INPUT_매출!G45
A31: 기타 매출 (수수료 등) | C31: =SUM(INPUT_매출!G48:INPUT_매출!G49)
A32: ◆ 매출합계 | C32: =INPUT_매출!G50
A34: ▶ COST TOTAL
A35: COS — 매출원가
A36: PT 강사료 | C36: =INPUT_비용!G6
A37: 입점업체 수수료 소계 | C37: =INPUT_비용!G11
A38: ∟ 입점업체 1 수수료 | C38: =INPUT_비용!G8
A39: ∟ 입점업체 2 수수료 | C39: =INPUT_비용!G9
A40: ∟ 입점업체 3 수수료 | C40: =INPUT_비용!G10
A41: 결제수수료 (총매출×2.16%) | C41: =INPUT_비용!G13
A42: COS 소계 | C42: =INPUT_비용!G14
...

Sheet 대시보드
A1: 피트니스 센터 P&L — 대시보드
B3: 총 매출 | E3: PB 매출 (핸들링)
B4: =P&L!C32 | E4: =P&L!C25
B6: Gross Profit | E6: GP 마진율
B7: =P&L!C61 | E7: =P&L!C62
B9: 영업이익 | E9: 영업이익률
B10: =P&L!C64 | E10: =P&L!C65
B12: BEP 매출 | E12: BEP 달성률
B13: =P&L!C71 | E13: =P&L!C73
A15: 경영 판단 체크리스트
B16: BEP 달성 | E16: =IF(P&L!C64>=0,"✅ BEP 달성","❌ BEP 미달")
B17: GP 마진율 ≥ 50% | E17: =IF(P&L!C62>=0.5,"✅ 양호 (≥50%)","❌ 주의 (<50%)")
B18: 영업이익률 ≥ 10% | E18: =IF(P&L!C65>=0.1,"✅ 양호 (≥10%)","❌ 주의 (<10%)")
B19: COS 비중 ≤ 30% | E19: =IF(IFERROR(INPUT_비용!G14/P&L!C32,1)<=0.3,"✅ 양호","❌ 주의")
B20: 인건비 비중 ≤ 45% | E20: =IF(IFERROR(INPUT_비용!G36/P&L!C32,1)<=0.45,"✅ 양호","❌ 주의")
B21: 임관비 비중 ≤ 25% | E21: =IF(IFERROR(INPUT_비용!G22/P&L!C32,1)<=0.25,"✅ 양호","❌ 주의")
B22: PT 매출 비중 ≥ 25% | E22: =IF(IFERROR(INPUT_매출!G32/P&L!C32,0)>=0.25,"✅ 양호","❌ 주의")
B23: 구독 잔존율 ≥ 80% | E23: =IF(INPUT_매출!F7>=80,"✅ 양호","❌ 주의")
B24: PT 전환율 ≥ 35% | E24: =IF(INPUT_매출!D27>=35,"✅ 양호","❌ 주의")

Sheet 월별아카이브
A1: 연도 | B1: 월 | C1: 구분(예측/실적) | D1: 총매출 | E1: PB매출 | F1: 입점업체매출 | G1: COS | H1: 비인건성SGA | I1: 인건비성SGA | J1: 총비용 | K1: GrossProfit | L1: GP마진율 | M1: 영업이익 | N1: 영업이익률 | O1: BEP매출 | P1: BEP달성률 | Q1: BEP여부 | R1: 구독잔존율(%) | S1: PT전환율(%) | T1: 저장일자
A2: ※ 매월 P&L 확정 후 3행 전체 복사 → 빈 행에 '값만 붙여넣기(Ctrl+Shift+V → 값)'하여 누적 기록하세요.
A3: 2026 | B3: 4 | C3: 예측 | D3: =P&L!C32 | E3: =INPUT_매출!G39 | F3: =INPUT_매출!G45 | G3: =INPUT_비용!G14 | H3: =INPUT_비용!G29 | I3: =INPUT_비용!G36 | J3: =INPUT_비용!G38 | K3: =P&L!C61 | L3: =P&L!C62 | M3: =P&L!C64 | N3: =P&L!C65 | O3: =P&L!C71 | P3: =P&L!C73 | Q3: =P&L!C74 | R3: =INPUT_매출!F7 | S3: =INPUT_매출!D27 | T3: =TEXT(TODAY(),"YYYY-MM-DD")
